Workbook

Sheet Supuestos
A1: CuentaFacil — Supuestos del modelo
A2: Edita solo las celdas en azul. Las de fondo amarillo son las que más mueven el resultado.
A3: Ejemplo: cambia "Precio del informe" a 60000 y mira el efecto en la hoja Balance.
A5: Supuesto | B5: Valor | C5: Unidad / fuente
A6: Precios (COP)
A7: Precio del informe | B7: 50000 | C7: Decisión del dueño (2026-10-10). Por contrato y por cuenta.
A8: Precio de configuración de contrato | B8: 15000 | C8: Decisión del dueño (2026-10-10). Cubre prórrogas y adiciones.
A9: Precio por mes adicional en cuentas unidas | B9: 25000 | C9: Propuesta (no aprobada). Pon 0 si se mantiene "un solo informe".
A10: % de cuentas que unen 2 meses | B10: 0 | C10: Supuesto. Cada cuenta unida suma 1 mes adicional.
A11: ¿Responsable de IVA? (1 = sí, 0 = no) | B11: 0 | C11: Si es 1, el precio se toma como IVA incluido. Tope: 3.500 UVT de ingresos al año.
A12: Tarifa de IVA | B12: 0.19 | C12: Estatuto Tributario, tarifa general.
A13: Valor UVT 2026 | B13: 52000 | C13: APROXIMADO — confirmar resolución DIAN de la UVT 2026.
A14: Volumen
A15: Contratos por contratista | B15: 1.43 | C15: Supuesto del plan (PLAN.md §4).
A16: Cuentas por contrato (duración media) | B16: 4 | C16: Supuesto: 1 contrato nuevo cada 4 cuentas.
A17: TRM (COP por US$) | B17: 4000 | C17: Referencia; actualizar con la TRM del mes.
A18: WhatsApp (Meta)
A19: Mensajes salientes por contratista al mes | B19: 200 | C19: Supuesto del plan.
A20: Mensajes de servicio gratis al mes | B20: 1000 | C20: Meta, desde 1-oct-2026 (fuente secundaria: confirmar).
A21: Precio por mensaje (utilidad/servicio) Colombia | B21: 0.0008 | C21: Fuente secundaria (Plivo/Wati). Confirmar en Administrador de WhatsApp › Precios.
A22: Plantillas de recordatorio por contratista | B22: 8 | C22: Supuesto del plan.
A23: Precio plantilla de bienvenida (marketing) | B23: 0.0125 | C23: Fuente secundaria: confirmar.
A24: Transcripción de audio
A25: Minutos de audio por contratista al mes | B25: 15 | C25: Supuesto.
A26: Precio por minuto | B26: 0.006 | C26: OpenAI gpt-4o-transcribe.
A27: Inteligencia artificial (Claude)
A28: IA por contratista (notas, fotos, intención — Haiku 5.5) | B28: 0.05 | C28: 40 notas × US$0,0005 + 100 mensajes × US$0,0003. Precios Claude 2026-10-06.
A29: IA por cuenta (soportes, redacción, control de calidad, correcciones — Sonnet 5.5) | B29: 0.405 | C29: 0,10 + 0,25 + 0,04 + 0,015.
A30: IA por configuración de contrato | B30: 0.14 | C30: Contrato + clausulado + informe anterior.
A31: Margen IA (reintentos, mensajes largos) | B31: 0.3 | C31: Supuesto.
A32: Infraestructura (US$ al mes)
A33: Supabase Pro | B33: 25 | C33: supabase.com/pricing.
A34: Supabase: cómputo/almacenamiento extra sobre el umbral | B34: 10 | C34: Supuesto.
A35: Umbral de cuentas para Supabase extra | B35: 200 | C35: Supuesto.
A36: Railway (bajo volumen) | B36: 20 | C36: Por uso; worker + panel.
A37: Railway (alto volumen) | B37: 30 | C37: Por uso.
A38: Umbral de cuentas para Railway alto | B38: 100 | C38: Supuesto.
A39: Recargo por pagar en dólares (comisión tarjeta + IVA servicios digitales) | B39: 0.15 | C39: Estimado; depende del banco y del proveedor.
A40: Cobro y bancos
A41: Comisión Wompi (%) | B41: 0.0265 | C41: wompi.com/es/co/planes-tarifas (plan agregador).
...

Sheet Balance
A1: CuentaFacil — Balance mensual por volumen (COP)
A2: Cambia el número de cuentas en la fila 4 (azul). Todo lo demás se calcula desde la hoja Supuestos.
A4: Cuentas al mes | B4: 50 | C4: 100 | D4: 200 | E4: 300
A5: Volumen
A6: Contratistas (aprox.) | B6: =ROUND(B4/Supuestos!$B$15,0) -> 35 | C6: =ROUND(C4/Supuestos!$B$15,0) -> 70 | D6: =ROUND(D4/Supuestos!$B$15,0) -> 140 | E6: =ROUND(E4/Supuestos!$B$15,0) -> 210
A7: Contratos nuevos (configuraciones) | B7: =B4/Supuestos!$B$16 -> 12.5 | C7: =C4/Supuestos!$B$16 -> 25 | D7: =D4/Supuestos!$B$16 -> 50 | E7: =E4/Supuestos!$B$16 -> 75
A8: Ingresos (precio de lista)
A9: Informes | B9: =B4*Supuestos!$B$7 -> 2500000 | C9: =C4*Supuestos!$B$7 -> 5000000 | D9: =D4*Supuestos!$B$7 -> 10000000 | E9: =E4*Supuestos!$B$7 -> 15000000
A10: Configuraciones | B10: =B7*Supuestos!$B$8 -> 187500 | C10: =C7*Supuestos!$B$8 -> 375000 | D10: =D7*Supuestos!$B$8 -> 750000 | E10: =E7*Supuestos!$B$8 -> 1125000
A11: Meses adicionales (cuentas unidas) | B11: =B4*Supuestos!$B$10*Supuestos!$B$9 -> 0 | C11: =C4*Supuestos!$B$10*Supuestos!$B$9 -> 0 | D11: =D4*Supuestos!$B$10*Supuestos!$B$9 -> 0 | E11: =E4*Supuestos!$B$10*Supuestos!$B$9 -> 0
A12: Total ingresos | B12: =SUM(B9:B11) -> 2687500 | C12: =SUM(C9:C11) -> 5375000 | D12: =SUM(D9:D11) -> 10750000 | E12: =SUM(E9:E11) -> 16125000
A13: IVA incluido en el precio (si eres responsable) | B13: =IF(Supuestos!$B$11=1,B12-B12/(1+Supuestos!$B$12),0) -> 0 | C13: =IF(Supuestos!$B$11=1,C12-C12/(1+Supuestos!$B$12),0) -> 0 | D13: =IF(Supuestos!$B$11=1,D12-D12/(1+Supuestos!$B$12),0) -> 0 | E13: =IF(Supuestos!$B$11=1,E12-E12/(1+Supuestos!$B$12),0) -> 0
A14: Ingresos netos de IVA | B14: =B12-B13 -> 2687500 | C14: =C12-C13 -> 5375000 | D14: =D12-D13 -> 10750000 | E14: =E12-E13 -> 16125000
A15: Tecnología
A16: IA (Claude) | B16: =(B6*Supuestos!$B$28+B4*Supuestos!$B$29+B7*Supuestos!$B$30)*(1+Supuestos!$B$31)*Supuestos!$B$17 -> 123500 | C16: =(C6*Supuestos!$B$28+C4*Supuestos!$B$29+C7*Supuestos!$B$30)*(1+Supuestos!$B$31)*Supuestos!$B$17 -> 247000 | D16: =(D6*Supuestos!$B$28+D4*Supuestos!$B$29+D7*Supuestos!$B$30)*(1+Supuestos!$B$31)*Supuestos!$B$17 -> 494000 | E16: =(E6*Supuestos!$B$28+E4*Supuestos!$B$29+E7*Supuestos!$B$30)*(1+Supuestos!$B$31)*Supuestos!$B$17 -> 741000
A17: WhatsApp (Meta) | B17: =(MAX(0,B6*Supuestos!$B$19-Supuestos!$B$20)*Supuestos!$B$21+B6*Supuestos!$B$22*Supuestos!$B$21+B7*Supuestos!$B$23)*Supuestos!$B$17 -> 20721 | C17: =(MAX(0,C6*Supuestos!$B$19-Supuestos!$B$20)*Supuestos!$B$21+C6*Supuestos!$B$22*Supuestos!$B$21+C7*Supuestos!$B$23)*Supuestos!$B$17 -> 44642 | D17: =(MAX(0,D6*Supuestos!$B$19-Supuestos!$B$20)*Supuestos!$B$21+D6*Supuestos!$B$22*Supuestos!$B$21+D7*Supuestos!$B$23)*Supuestos!$B$17 -> 92484 | E17: =(MAX(0,E6*Supuestos!$B$19-Supuestos!$B$20)*Supuestos!$B$21+E6*Supuestos!$B$22*Supuestos!$B$21+E7*Supuestos!$B$23)*Supuestos!$B$17 -> 140326
A18: Transcripción de audios | B18: =B6*Supuestos!$B$25*Supuestos!$B$26*Supuestos!$B$17 -> 12600 | C18: =C6*Supuestos!$B$25*Supuestos!$B$26*Supuestos!$B$17 -> 25200 | D18: =D6*Supuestos!$B$25*Supuestos!$B$26*Supuestos!$B$17 -> 50400 | E18: =E6*Supuestos!$B$25*Supuestos!$B$26*Supuestos!$B$17 -> 75600
A19: Supabase | B19: =(Supuestos!$B$33+IF(B4>Supuestos!$B$35,Supuestos!$B$34,0))*Supuestos!$B$17 -> 100000 | C19: =(Supuestos!$B$33+IF(C4>Supuestos!$B$35,Supuestos!$B$34,0))*Supuestos!$B$17 -> 100000 | D19: =(Supuestos!$B$33+IF(D4>Supuestos!$B$35,Supuestos!$B$34,0))*Supuestos!$B$17 -> 100000 | E19: =(Supuestos!$B$33+IF(E4>Supuestos!$B$35,Supuestos!$B$34,0))*Supuestos!$B$17 -> 140000
A20: Railway | B20: =IF(B4>Supuestos!$B$38,Supuestos!$B$37,Supuestos!$B$36)*Supuestos!$B$17 -> 80000 | C20: =IF(C4>Supuestos!$B$38,Supuestos!$B$37,Supuestos!$B$36)*Supuestos!$B$17 -> 80000 | D20: =IF(D4>Supuestos!$B$38,Supuestos!$B$37,Supuestos!$B$36)*Supuestos!$B$17 -> 120000 | E20: =IF(E4>Supuestos!$B$38,Supuestos!$B$37,Supuestos!$B$36)*Supuestos!$B$17 -> 120000
A21: Recargo por pagos en dólares | B21: =SUM(B16:B20)*Supuestos!$B$39 -> 50523.15 | C21: =SUM(C16:C20)*Supuestos!$B$39 -> 74526.3 | D21: =SUM(D16:D20)*Supuestos!$B$39 -> 128532.6 | E21: =SUM(E16:E20)*Supuestos!$B$39 -> 182538.9
A22: Cobro y bancos
A23: Comisión Wompi | B23: =(B12*Supuestos!$B$41+(B4+B7)*Supuestos!$B$42)*(1+Supuestos!$B$43)*Supuestos!$B$44 -> 109450.25 | C23: =(C12*Supuestos!$B$41+(C4+C7)*Supuestos!$B$42)*(1+Supuestos!$B$43)*Supuestos!$B$44 -> 218900.5 | D23: =(D12*Supuestos!$B$41+(D4+D7)*Supuestos!$B$42)*(1+Supuestos!$B$43)*Supuestos!$B$44 -> 437801 | E23: =(E12*Supuestos!$B$41+(E4+E7)*Supuestos!$B$42)*(1+Supuestos!$B$43)*Supuestos!$B$44 -> 656701.5
A24: GMF (4×1.000) | B24: =B12*Supuestos!$B$45 -> 10750 | C24: =C12*Supuestos!$B$45 -> 21500 | D24: =D12*Supuestos!$B$45 -> 43000 | E24: =E12*Supuestos!$B$45 -> 64500
A25: Operación
A26: Línea, dominio y correo | B26: =Supuestos!$B$47 -> 65000 | C26: =Supuestos!$B$47 -> 65000 | D26: =Supuestos!$B$47 -> 65000 | E26: =Supuestos!$B$47 -> 65000
A27: Contador y facturación electrónica | B27: =IF(B4>Supuestos!$B$50,Supuestos!$B$49,Supuestos!$B$48) -> 150000 | C27: =IF(C4>Supuestos!$B$50,Supuestos!$B$49,Supuestos!$B$48) -> 340000 | D27: =IF(D4>Supuestos!$B$50,Supuestos!$B$49,Supuestos!$B$48) -> 340000 | E27: =IF(E4>Supuestos!$B$50,Supuestos!$B$49,Supuestos!$B$48) -> 340000
A28: Tu tiempo | B28: =B4*Supuestos!$B$51/60*Supuestos!$B$52 -> 300000 | C28: =C4*Supuestos!$B$51/60*Supuestos!$B$52 -> 600000 | D28: =D4*Supuestos!$B$51/60*Supuestos!$B$52 -> 1200000 | E28: =E4*Supuestos!$B$51/60*Supuestos!$B$52 -> 1800000
A29: Contingencias | B29: =B14*Supuestos!$B$53 -> 80625 | C29: =C14*Supuestos!$B$53 -> 161250 | D29: =D14*Supuestos!$B$53 -> 322500 | E29: =E14*Supuestos!$B$53 -> 483750
A30: Impuestos: renta + ICA (provisión) | B30: =B14*Supuestos!$B$54 -> 188125 | C30: =C14*Supuestos!$B$54 -> 376250 | D30: =D14*Supuestos!$B$54 -> 752500 | E30: =E14*Supuestos!$B$54 -> 1128750
A31: Total costos | B31: =SUM(B16:B20)+B21+B23+B24+SUM(B26:B30) -> 1291294.4 | C31: =SUM(C16:C20)+C21+C23+C24+SUM(C26:C30) -> 2354268.8 | D31: =SUM(D16:D20)+D21+D23+D24+SUM(D26:D30) -> 4146217.6 | E31: =SUM(E16:E20)+E21+E23+E24+SUM(E26:E30) -> 5938166.4
A32: Resultado
A33: Utilidad neta | B33: =B14-B31 -> 1396205.6 | C33: =C14-C31 -> 3020731.2 | D33: =D14-D31 -> 6603782.4 | E33: =E14-E31 -> 10186834
A34: Margen neto | B34: =IF(B14=0,0,B33/B14) -> 0.51951836 | C34: =IF(C14=0,0,C33/C14) -> 0.5619965 | D34: =IF(D14=0,0,D33/D14) -> 0.61430534 | E34: =IF(E14=0,0,E33/E14) -> 0.63174162
A35: Costo total por cuenta | B35: =IF(B4=0,0,B31/B4) -> 25825.888 | C35: =IF(C4=0,0,C31/C4) -> 23542.688 | D35: =IF(D4=0,0,D31/D4) -> 20731.088 | E35: =IF(E4=0,0,E31/E4) -> 19793.888
A36: Costo por cuenta sin tu tiempo ni impuestos | B36: =IF(B4=0,0,(B31-B28-B30)/B4) -> 16063.388 | C36: =IF(C4=0,0,(C31-C28-C30)/C4) -> 13780.188 | D36: =IF(D4=0,0,(D31-D28-D30)/D4) -> 10968.588 | E36: =IF(E4=0,0,(E31-E28-E30)/E4) -> 10031.388
A37: Utilidad por cuenta | B37: =IF(B4=0,0,B33/B4) -> 27924.112 | C37: =IF(C4=0,0,C33/C4) -> 30207.312 | D37: =IF(D4=0,0,D33/D4) -> 33018.912 | E37: =IF(E4=0,0,E33/E4) -> 33956.112
A38: Horas tuyas al mes | B38: =B4*Supuestos!$B$51/60 -> 10 | C38: =C4*Supuestos!$B$51/60 -> 20 | D38: =D4*Supuestos!$B$51/60 -> 40 | E38: =E4*Supuestos!$B$51/60 -> 60
A39: Costos fijos del mes | B39: =B19+B20+(B19+B20)*Supuestos!$B$39+B26+B27 -> 422000 | C39: =C19+C20+(C19+C20)*Supuestos!$B$39+C26+C27 -> 612000 | D39: =D19+D20+(D19+D20)*Supuestos!$B$39+D26+D27 -> 658000 | E39: =E19+E20+(E19+E20)*Supuestos!$B$39+E26+E27 -> 704000
A40: Punto de equilibrio (cuentas al mes) | B40: =IFERROR(B39/((B14-(B31-B39))/B4),0) -> 11.604848 | C40: =IFERROR(C39/((C14-(C31-C39))/C4),0) -> 16.846829 | D40: =IFERROR(D39/((D14-(D31-D39))/D4),0) -> 18.122273 | E40: =IFERROR(E39/((E14-(E31-E39))/E4),0) -> 19.392455
A41: Ingresos al año | B41: =B12*12 -> 32250000 | C41: =C12*12 -> 64500000 | D41: =D12*12 -> 129000000 | E41: =E12*12 -> 193500000
...

Sheet Gestores
A1: CuentaFacil — Escenario de gestores (COP al mes)
A2: Las cuentas directas vienen de la fila 4 de Balance; los supuestos de gestores, de Supuestos (filas 57-62).
A4: Cuentas directas sin gestores (de Balance) | B4: =Balance!B4 -> 50 | C4: =Balance!C4 -> 100 | D4: =Balance!D4 -> 200 | E4: =Balance!E4 -> 300
A5: Volumen
A6: Cuentas de gestores | B6: =B4*Supuestos!$B$60 -> 25 | C6: =C4*Supuestos!$B$60 -> 50 | D6: =D4*Supuestos!$B$60 -> 100 | E6: =E4*Supuestos!$B$60 -> 150
A7: … que ya eran clientes directos (migran) | B7: =B6*Supuestos!$B$61 -> 6.25 | C7: =C6*Supuestos!$B$61 -> 12.5 | D7: =D6*Supuestos!$B$61 -> 25 | E7: =E6*Supuestos!$B$61 -> 37.5
A8: … contratistas nuevos que trae el gestor | B8: =B6-B7 -> 18.75 | C8: =C6-C7 -> 37.5 | D8: =D6-D7 -> 75 | E8: =E6-E7 -> 112.5
A9: Cuentas directas que quedan a precio de lista | B9: =B4-B7 -> 43.75 | C9: =C4-C7 -> 87.5 | D9: =D4-D7 -> 175 | E9: =E4-E7 -> 262.5
A10: Total de cuentas al mes | B10: =B9+B6 -> 68.75 | C10: =C9+C6 -> 137.5 | D10: =D9+D6 -> 275 | E10: =E9+E6 -> 412.5
A11: Contratistas (aprox.) | B11: =ROUND(B10/Supuestos!$B$15,0) -> 48 | C11: =ROUND(C10/Supuestos!$B$15,0) -> 96 | D11: =ROUND(D10/Supuestos!$B$15,0) -> 192 | E11: =ROUND(E10/Supuestos!$B$15,0) -> 288
A12: Contratos nuevos (configuraciones) | B12: =B10/Supuestos!$B$16 -> 17.1875 | C12: =C10/Supuestos!$B$16 -> 34.375 | D12: =D10/Supuestos!$B$16 -> 68.75 | E12: =E10/Supuestos!$B$16 -> 103.125
A13: Gestores activos (aprox.) | B13: =IF(Supuestos!$B$59=0,0,B6/Supuestos!$B$59) -> 3.125 | C13: =IF(Supuestos!$B$59=0,0,C6/Supuestos!$B$59) -> 6.25 | D13: =IF(Supuestos!$B$59=0,0,D6/Supuestos!$B$59) -> 12.5 | E13: =IF(Supuestos!$B$59=0,0,E6/Supuestos!$B$59) -> 18.75
A14: Ingresos
A15: Informes directos (precio de lista) | B15: =B9*Supuestos!$B$7 -> 2187500 | C15: =C9*Supuestos!$B$7 -> 4375000 | D15: =D9*Supuestos!$B$7 -> 8750000 | E15: =E9*Supuestos!$B$7 -> 13125000
A16: Informes de gestores (precio preferencial) | B16: =B6*Supuestos!$B$57 -> 750000 | C16: =C6*Supuestos!$B$57 -> 1500000 | D16: =D6*Supuestos!$B$57 -> 3000000 | E16: =E6*Supuestos!$B$57 -> 4500000
A17: Configuraciones | B17: =B12*Supuestos!$B$8 -> 257812.5 | C17: =C12*Supuestos!$B$8 -> 515625 | D17: =D12*Supuestos!$B$8 -> 1031250 | E17: =E12*Supuestos!$B$8 -> 1546875
A18: Meses adicionales (cuentas unidas) | B18: =B10*Supuestos!$B$10*Supuestos!$B$9 -> 0 | C18: =C10*Supuestos!$B$10*Supuestos!$B$9 -> 0 | D18: =D10*Supuestos!$B$10*Supuestos!$B$9 -> 0 | E18: =E10*Supuestos!$B$10*Supuestos!$B$9 -> 0
A19: Total ingresos | B19: =SUM(B15:B18) -> 3195312.5 | C19: =SUM(C15:C18) -> 6390625 | D19: =SUM(D15:D18) -> 12781250 | E19: =SUM(E15:E18) -> 19171875
A20: IVA incluido en el precio (si eres responsable) | B20: =IF(Supuestos!$B$11=1,B19-B19/(1+Supuestos!$B$12),0) -> 0 | C20: =IF(Supuestos!$B$11=1,C19-C19/(1+Supuestos!$B$12),0) -> 0 | D20: =IF(Supuestos!$B$11=1,D19-D19/(1+Supuestos!$B$12),0) -> 0 | E20: =IF(Supuestos!$B$11=1,E19-E19/(1+Supuestos!$B$12),0) -> 0
A21: Ingresos netos de IVA | B21: =B19-B20 -> 3195312.5 | C21: =C19-C20 -> 6390625 | D21: =D19-D20 -> 12781250 | E21: =E19-E20 -> 19171875
A22: Costos
A23: IA (Claude) | B23: =(B11*Supuestos!$B$28+B10*Supuestos!$B$29+B12*Supuestos!$B$30)*(1+Supuestos!$B$31)*Supuestos!$B$17 -> 169780 | C23: =(C11*Supuestos!$B$28+C10*Supuestos!$B$29+C12*Supuestos!$B$30)*(1+Supuestos!$B$31)*Supuestos!$B$17 -> 339560 | D23: =(D11*Supuestos!$B$28+D10*Supuestos!$B$29+D12*Supuestos!$B$30)*(1+Supuestos!$B$31)*Supuestos!$B$17 -> 679120 | E23: =(E11*Supuestos!$B$28+E10*Supuestos!$B$29+E12*Supuestos!$B$30)*(1+Supuestos!$B$31)*Supuestos!$B$17 -> 1018680
A24: WhatsApp (Meta) | B24: =(MAX(0,B11*Supuestos!$B$19-Supuestos!$B$20)*Supuestos!$B$21+B11*Supuestos!$B$22*Supuestos!$B$21+B12*Supuestos!$B$23)*Supuestos!$B$17 -> 29608.175 | C24: =(MAX(0,C11*Supuestos!$B$19-Supuestos!$B$20)*Supuestos!$B$21+C11*Supuestos!$B$22*Supuestos!$B$21+C12*Supuestos!$B$23)*Supuestos!$B$17 -> 62416.35 | D24: =(MAX(0,D11*Supuestos!$B$19-Supuestos!$B$20)*Supuestos!$B$21+D11*Supuestos!$B$22*Supuestos!$B$21+D12*Supuestos!$B$23)*Supuestos!$B$17 -> 128032.7 | E24: =(MAX(0,E11*Supuestos!$B$19-Supuestos!$B$20)*Supuestos!$B$21+E11*Supuestos!$B$22*Supuestos!$B$21+E12*Supuestos!$B$23)*Supuestos!$B$17 -> 193649.05
A25: Transcripción de audios | B25: =B11*Supuestos!$B$25*Supuestos!$B$26*Supuestos!$B$17 -> 17280 | C25: =C11*Supuestos!$B$25*Supuestos!$B$26*Supuestos!$B$17 -> 34560 | D25: =D11*Supuestos!$B$25*Supuestos!$B$26*Supuestos!$B$17 -> 69120 | E25: =E11*Supuestos!$B$25*Supuestos!$B$26*Supuestos!$B$17 -> 103680
A26: Supabase | B26: =(Supuestos!$B$33+IF(B10>Supuestos!$B$35,Supuestos!$B$34,0))*Supuestos!$B$17 -> 100000 | C26: =(Supuestos!$B$33+IF(C10>Supuestos!$B$35,Supuestos!$B$34,0))*Supuestos!$B$17 -> 100000 | D26: =(Supuestos!$B$33+IF(D10>Supuestos!$B$35,Supuestos!$B$34,0))*Supuestos!$B$17 -> 140000 | E26: =(Supuestos!$B$33+IF(E10>Supuestos!$B$35,Supuestos!$B$34,0))*Supuestos!$B$17 -> 140000
A27: Railway | B27: =IF(B10>Supuestos!$B$38,Supuestos!$B$37,Supuestos!$B$36)*Supuestos!$B$17 -> 80000 | C27: =IF(C10>Supuestos!$B$38,Supuestos!$B$37,Supuestos!$B$36)*Supuestos!$B$17 -> 120000 | D27: =IF(D10>Supuestos!$B$38,Supuestos!$B$37,Supuestos!$B$36)*Supuestos!$B$17 -> 120000 | E27: =IF(E10>Supuestos!$B$38,Supuestos!$B$37,Supuestos!$B$36)*Supuestos!$B$17 -> 120000
A28: Recargo por pagos en dólares | B28: =SUM(B23:B27)*Supuestos!$B$39 -> 59500.226 | C28: =SUM(C23:C27)*Supuestos!$B$39 -> 98480.452 | D28: =SUM(D23:D27)*Supuestos!$B$39 -> 170440.9 | E28: =SUM(E23:E27)*Supuestos!$B$39 -> 236401.36
A29: Comisión Wompi (un pago agrupado por gestor) | B29: =(B19*Supuestos!$B$41+(B9+B13+B12)*Supuestos!$B$42)*(1+Supuestos!$B$43)*Supuestos!$B$44 -> 123302.59 | C29: =(C19*Supuestos!$B$41+(C9+C13+C12)*Supuestos!$B$42)*(1+Supuestos!$B$43)*Supuestos!$B$44 -> 246605.19 | D29: =(D19*Supuestos!$B$41+(D9+D13+D12)*Supuestos!$B$42)*(1+Supuestos!$B$43)*Supuestos!$B$44 -> 493210.38 | E29: =(E19*Supuestos!$B$41+(E9+E13+E12)*Supuestos!$B$42)*(1+Supuestos!$B$43)*Supuestos!$B$44 -> 739815.56
A30: GMF (4×1.000) | B30: =B19*Supuestos!$B$45 -> 12781.25 | C30: =C19*Supuestos!$B$45 -> 25562.5 | D30: =D19*Supuestos!$B$45 -> 51125 | E30: =E19*Supuestos!$B$45 -> 76687.5
A31: Línea, dominio y correo | B31: =Supuestos!$B$47 -> 65000 | C31: =Supuestos!$B$47 -> 65000 | D31: =Supuestos!$B$47 -> 65000 | E31: =Supuestos!$B$47 -> 65000
A32: Contador y facturación electrónica | B32: =IF(B10>Supuestos!$B$50,Supuestos!$B$49,Supuestos!$B$48) -> 340000 | C32: =IF(C10>Supuestos!$B$50,Supuestos!$B$49,Supuestos!$B$48) -> 340000 | D32: =IF(D10>Supuestos!$B$50,Supuestos!$B$49,Supuestos!$B$48) -> 340000 | E32: =IF(E10>Supuestos!$B$50,Supuestos!$B$49,Supuestos!$B$48) -> 340000
A33: Tu tiempo | B33: =(B9*Supuestos!$B$51+B6*Supuestos!$B$62)/60*Supuestos!$B$52 -> 337500 | C33: =(C9*Supuestos!$B$51+C6*Supuestos!$B$62)/60*Supuestos!$B$52 -> 675000 | D33: =(D9*Supuestos!$B$51+D6*Supuestos!$B$62)/60*Supuestos!$B$52 -> 1350000 | E33: =(E9*Supuestos!$B$51+E6*Supuestos!$B$62)/60*Supuestos!$B$52 -> 2025000
A34: Contingencias | B34: =B21*Supuestos!$B$53 -> 95859.375 | C34: =C21*Supuestos!$B$53 -> 191718.75 | D34: =D21*Supuestos!$B$53 -> 383437.5 | E34: =E21*Supuestos!$B$53 -> 575156.25
A35: Impuestos: renta + ICA (provisión) | B35: =B21*Supuestos!$B$54 -> 223671.88 | C35: =C21*Supuestos!$B$54 -> 447343.75 | D35: =D21*Supuestos!$B$54 -> 894687.5 | E35: =E21*Supuestos!$B$54 -> 1342031.2
A36: Total costos | B36: =SUM(B23:B35) -> 1654283.5 | C36: =SUM(C23:C35) -> 2746247 | D36: =SUM(D23:D35) -> 4884174 | E36: =SUM(E23:E35) -> 6976101
A37: Resultado
A38: Utilidad neta con gestores | B38: =B21-B36 -> 1541029 | C38: =C21-C36 -> 3644378 | D38: =D21-D36 -> 7897076 | E38: =E21-E36 -> 12195774
A39: Utilidad neta sin gestores (de Balance) | B39: =Balance!B33 -> 1396205.6 | C39: =Balance!C33 -> 3020731.2 | D39: =Balance!D33 -> 6603782.4 | E39: =Balance!E33 -> 10186834
A40: Diferencia: lo que suman los gestores | B40: =B38-B39 -> 144823.4 | C40: =C38-C39 -> 623646.81 | D40: =D38-D39 -> 1293293.6 | E40: =E38-E39 -> 2008940.4
A41: Margen neto con gestores | B41: =IF(B21=0,0,B38/B21) -> 0.48227803 | C41: =IF(C21=0,0,C38/C21) -> 0.57026942 | D41: =IF(D21=0,0,D38/D21) -> 0.61786414 | E41: =IF(E21=0,0,E38/E21) -> 0.63612839
...

Sheet Conclusión
A1: Conclusión (con los supuestos por defecto)
A3: 1. Los precios son convenientes: el informe de $50.000 deja un margen neto alto aun pagando tu tiempo e impuestos estimados, y el punto de equilibrio es bajo (ver fila "Punto de equilibrio" en Balance).
A4: 2. Para el contratista es barato: ≈1,25 % de unos honorarios de $4.000.000 y ≈2,5 % de $2.000.000, y le ahorra horas de trabajo.
A5: 3. Configuración a $15.000: ya no es solo un filtro; cubre su comisión de Wompi, la IA y unos minutos de revisión.
A6: 4. IVA: hacia ~290 cuentas al mes los ingresos anuales superan 3.500 UVT. Recomendación: publicar los precios como "IVA incluido" desde el inicio. Prueba poniendo 1 en "¿Responsable de IVA?" para ver el impacto.
A7: 5. Cuentas unidas: si se cobran como un solo informe, cada mes unido reduce el ingreso por mes trabajado. Prueba subir "% de cuentas que unen 2 meses" con y sin precio por mes adicional.
A8: 6. Tu tiempo es el límite real: revisa la fila "Horas tuyas al mes". Por encima de ~250 cuentas conviene contratar apoyo.
A9: 7. Supuestos a confirmar: tarifa WhatsApp Colombia, UVT 2026, provisión de impuestos (contador), TRM del mes.
A10: ="8. Gestores (hoja Gestores, con 100 cuentas directas): cada cuenta de gestor a "&TEXT(Supuestos!B57,"$#,##0")&" deja "&TEXT(Gestores!C47,"$#,##0")&" y una directa "&TEXT(Gestores!C46,"$#,##0")&". Con los supuestos, los gestores suman "&TEXT(Gestores!C40,"$#,##0")&" al mes." -> 8. Gestores (hoja Gestores, con 100 cuentas directas): cada cuenta de gestor a $30,000 deja $20,099 y una directa $33,931. Con los supuestos, los gestores suman $623,647 al mes.
A11: ="9. El riesgo es la canibalización: cada cliente que pasa de $50.000 a precio de gestor resta "&TEXT(Gestores!C48,"$#,##0")&"; se compensa con "&TEXT(Gestores!C49,"0.0")&" cuentas nuevas de gestor. Mientras menos del "&TEXT(Gestores!C50,"0%")&" de las cuentas de gestores sean clientes que ya pagaban precio de lista, el escenario gana. Exige un mínimo de personas activas por gestor (Supuestos B58)." -> 9. El riesgo es la canibalización: cada cliente que pasa de $50.000 a precio de gestor resta $13,832; se compensa con 0.7 cuentas nuevas de gestor. Mientras menos del 59% de las cuentas de gestores sean clientes que ya pagaban precio de lista, el escenario gana. Exige un mínimo de personas activas por gestor (Supuestos B58).
